<?xml version="1.0" ?>
<!-- =================================================================================== -->
<!-- |    This document was autogenerated by xacro from demo05_car_base.urdf.xacro     | -->
<!-- |    EDITING THIS FILE BY HAND IS NOT RECOMMENDED                                 | -->
<!-- =================================================================================== -->
<robot name="mycar" xmlns:xacro="http://wiki.ros.org/xacro">
  <link name="base_footprint">
    <visual>
      <geometry>
        <sphere radius="0.001"/>
      </geometry>
    </visual>
  </link>
  <!-- 2-1 link -->
  <link name="base_link">
    <visual>
      <geometry>
        <cylinder length="0.08" radius="0.1"/>
      </geometry>
      <origin rpy="0 0 0" xyz="0 0 0"/>
      <material name="baselink_color">
        <color rgba="1.0 0.5 0.2 0.5"/>
      </material>
    </visual>
  </link>
  <!-- 2-2 joint -->
  <joint name="link2footprint" type="fixed">
    <parent link="base_footprint"/>
    <child link="base_link"/>
    <origin rpy="0 0 0" xyz="0 0 0.055"/>
  </joint>
  <!-- 3-1 link -->
  <link name="left_wheel">
    <visual>
      <geometry>
        <cylinder length="0.015" radius="0.0325"/>
      </geometry>
      <origin rpy="1.57079635 0 0" xyz="0 0 0"/>
      <material name="wheel_color">
        <color rgba="0 0 0 0.3"/>
      </material>
    </visual>
  </link>
  <!-- 3-2 joint -->
  <joint name="left2link" type="continuous">
    <parent link="base_link"/>
    <child link="left_wheel"/>
    <origin rpy="0 0 0" xyz="0 0.1 -0.0225"/>
    <axis xyz="0 1 0"/>
  </joint>
  <!-- 3-1 link -->
  <link name="right_wheel">
    <visual>
      <geometry>
        <cylinder length="0.015" radius="0.0325"/>
      </geometry>
      <origin rpy="1.57079635 0 0" xyz="0 0 0"/>
      <material name="wheel_color">
        <color rgba="0 0 0 0.3"/>
      </material>
    </visual>
  </link>
  <!-- 3-2 joint -->
  <joint name="right2link" type="continuous">
    <parent link="base_link"/>
    <child link="right_wheel"/>
    <origin rpy="0 0 0" xyz="0 -0.1 -0.0225"/>
    <axis xyz="0 1 0"/>
  </joint>
  <!-- 4-1 link -->
  <link name="front_wheel">
    <visual>
      <geometry>
        <sphere radius="0.0075"/>
      </geometry>
      <origin rpy="0 0 0" xyz="0 0 0"/>
      <material name="wheel_color">
        <color rgba="0 0 0 0.3"/>
      </material>
    </visual>
  </link>
  <!-- 4-2 joint -->
  <joint name="front2link" type="continuous">
    <parent link="base_link"/>
    <child link="front_wheel"/>
    <origin rpy="0 0 0" xyz="0.08 0 -0.0475"/>
    <axis xyz="0 1 0"/>
  </joint>
  <!-- 4-1 link -->
  <link name="back_wheel">
    <visual>
      <geometry>
        <sphere radius="0.0075"/>
      </geometry>
      <origin rpy="0 0 0" xyz="0 0 0"/>
      <material name="wheel_color">
        <color rgba="0 0 0 0.3"/>
      </material>
    </visual>
  </link>
  <!-- 4-2 joint -->
  <joint name="back2link" type="continuous">
    <parent link="base_link"/>
    <child link="back_wheel"/>
    <origin rpy="0 0 0" xyz="-0.08 0 -0.0475"/>
    <axis xyz="0 1 0"/>
  </joint>
</robot>

